const Task = require("../models/tasks");
const asyncWrapper = require("../middleware/async");
const { createCusutomError } = require("../errors/customer-error");

//using asyncWrapper middle ware to avoid the try try try we are using eveyrhwere
const getAllTasks = asyncWrapper(async (req, res) => {
  const tasks = await Task.find({});
  res.status(200).json({ tasks: tasks });
});

const createTask = asyncWrapper(async (req, res) => {
  try {
    //creating a new docs
    const task = await Task.create(req.body);
    res.status(201).json({ task });
  } catch (error) {
    res.status(500).json({ msg: error });
  }
});

const getSingleTasks = asyncWrapper(async (req, res, next) => {
  const { id: taskID } = req.params;
  const task = await Task.findOne({ _id: taskID });
  if (!task) {
    return next(createCusutomError(`No task with id : ${taskID}`, 404));
    // return res.status(404).json({ msg: `No task with id : ${taskID}` });
  }
  res.status(200).json({ task });
});

const updateTask = asyncWrapper(async (req, res, next) => {
  const { id: taskID } = req.params;

  const task = await Task.findOneAndUpdate({ _id: taskID }, req.body, {
    new: true,
    runValidators: true,
  });
  if (!task) {
    return next(createCusutomError(`No task with id : ${taskID}`, 404));
  }
  res.status(200).json({ task });
});

const deleteTask = asyncWrapper(async (req, res) => {
  const { id: taskID } = req.params;
  const task = await Task.findOneAndDelete({ _id: taskID });
  if (!task) {
    return next(createCusutomError(`No task with id : ${taskID}`, 404));
  }
  res.status(200).json({ task });
});

module.exports = {
  getAllTasks,
  createTask,
  getSingleTasks,
  updateTask,
  deleteTask,
};
